<?xml version="1.0" encoding="utf-8"?>
<!-- This URDF was automatically created by SolidWorks to URDF Exporter! Originally created by Stephen Brawner (brawner@gmail.com) 
     Commit Version: 1.6.0-4-g7f85cfe  Build Version: 1.6.7995.38578
     For more information, please see http://wiki.ros.org/sw_urdf_exporter -->
<robot
  name="rlautocar">
  <gazebo>
    <plugin filename="libgazebo_ros_diff_drive.so" name="diff_drive">
      <ros>
        <argument>--ros-args --remap ~/cmd_vel:=cmd_vel</argument>
        <argument>--ros-args --remap ~/odom:=odom</argument>
      </ros>
      <!-- wheels -->
      <left_joint>wheel_L</left_joint>
      <right_joint>wheel_R</right_joint>
      <!-- kinematics -->
      <wheel_separation>0.45</wheel_separation>
      <wheel_diameter>0.130</wheel_diameter>
      <!-- limits -->
      <max_wheel_torque>30</max_wheel_torque>
      <max_wheel_acceleration>1.0</max_wheel_acceleration>
      <!-- output -->
      <publish_odom>true</publish_odom>
      <publish_odom_tf>true</publish_odom_tf>
      <publish_wheel_tf>true</publish_wheel_tf>
      <odometry_frame>odom</odometry_frame>
      <robot_base_frame>robot_footprint</robot_base_frame>
    </plugin>
  </gazebo>
  <gazebo reference="hokuyo">
    <sensor name="head_hokuyo_sensor" type="ray">
      <pose>0 0 0 0 0 0</pose>
      <visualize>true</visualize>
      <update_rate>40</update_rate>
      <ray>
        <scan>
          <horizontal>
            <samples>360</samples>
            <resolution>1</resolution>
            <min_angle>-3.14</min_angle>
            <max_angle>3.14</max_angle>
          </horizontal>
        </scan>
        <range>
          <min>0.120</min>
          <max>10.0</max>
          <resolution>0.015</resolution>
        </range>
        <noise>
          <type>gaussian</type>
          <!-- Noise parameters based on published spec for Hokuyo laser
                achieving "+-30mm" accuracy at range < 10m.  A mean of 0.0m and
                stddev of 0.01m will put 99.7% of samples within 0.03m of the true
                reading. -->
          <mean>0.0</mean>
          <stddev>0.01</stddev>
        </noise>
      </ray>
      <update_rate>30</update_rate>
      <plugin filename="libgazebo_ros_ray_sensor.so" name="gazebo_ros_head_hokuyo_controller">
        <ros>
          <argument>--ros-args --remap ~/out:=scan</argument>
        </ros>
        <output_type>sensor_msgs/LaserScan</output_type>
      </plugin>
    </sensor>
  </gazebo>
  <link name="robot_footprint"/>
  <joint name="robot_footprint_joint" type="fixed">
    <origin rpy="0 0 0" xyz="0 0 0"/>
    <parent link="robot_footprint"/>
    <child link="base_link"/>
  </joint>
  <link
    name="base_link">
    <inertial>
      <origin
        xyz="-0.00934511761383974 2.77555756156289E-17 0.0483024889212149"
        rpy="0 0 0" />
      <mass
        value="2.67199357071076" />
      <inertia
        ixx="0.0207823672001074"
        ixy="-2.65857264863415E-18"
        ixz="0.000135067236943802"
        iyy="0.0507439803899983"
        iyz="-5.83000997071158E-19"
        izz="0.0701498963353498" />
    </inertial>
    <visual>
      <origin
        xyz="0 0 0"
        rpy="0 0 0" />
      <geometry>
        <mesh
          filename="install/slam/share/slam/meshes/base_link1.STL" />
      </geometry>
      <material
        name="">
        <color
          rgba="0.792156862745098 0.819607843137255 0.933333333333333 1" />
      </material>
    </visual>
    <collision>
      <origin
        xyz="0 0 0"
        rpy="0 0 0" />
      <geometry>
        <mesh
          filename="install/slam/share/slam/meshes/base_link1.STL" />
      </geometry>
    </collision>
  </link>
  <link
    name="link_BR">
    <inertial>
      <origin
        xyz="4.44089209850063E-16 -0.0300000000000004 -5.55111512312578E-16"
        rpy="0 0 0" />
      <mass
        value="0.794697277652074" />
      <inertia
        ixx="0.00107959625169034"
        ixy="5.17435008151134E-20"
        ixz="-8.09033239265895E-20"
        iyy="0.00168237413678944"
        iyz="1.46656822717915E-18"
        izz="0.00107959625169034" />
    </inertial>
    <visual>
      <origin
        xyz="0 0 0"
        rpy="0 0 0" />
      <geometry>
        <mesh
          filename="install/slam/share/slam/meshes/link_BR1.STL" />
      </geometry>
      <material
        name="">
        <color
          rgba="0.792156862745098 0.819607843137255 0.933333333333333 1" />
      </material>
    </visual>
    <collision>
      <origin
        xyz="0 0 0"
        rpy="0 0 0" />
      <geometry>
        <mesh
          filename="install/slam/share/slam/meshes/link_BR1.STL" />
      </geometry>
    </collision>
  </link>
  <joint
    name="wheel_R"
    type="continuous">
    <origin
      xyz="-0.16247 -0.1988 0.025"
      rpy="0 0 0" />
    <parent
      link="base_link" />
    <child
      link="link_BR" />
    <axis
      xyz="0 1 0" />
    <limit effort="10000" velocity="1000"/>
    <dynamics damping="1.0" friction="1.0"/>
  </joint>
  <link
    name="link_BL">
    <inertial>
      <origin
        xyz="0 0.0300000000000002 2.22044604925031E-16"
        rpy="0 0 0" />
      <mass
        value="0.794697277652074" />
      <inertia
        ixx="0.00107959625169034"
        ixy="1.76941166711853E-19"
        ixz="-5.54040275162219E-20"
        iyy="0.00168237413678944"
        iyz="4.8223667028016E-19"
        izz="0.00107959625169034" />
    </inertial>
    <visual>
      <origin
        xyz="0 0 0"
        rpy="0 0 0" />
      <geometry>
        <mesh
          filename="install/slam/share/slam/meshes/link_BL1.STL" />
      </geometry>
      <material
        name="">
        <color
          rgba="0.792156862745098 0.819607843137255 0.933333333333333 1" />
      </material>
    </visual>
    <collision>
      <origin
        xyz="0 0 0"
        rpy="0 0 0" />
      <geometry>
        <mesh
          filename="install/slam/share/slam/meshes/link_BL1.STL" />
      </geometry>
    </collision>
  </link>
  <joint
    name="wheel_L"
    type="continuous">
    <origin
      xyz="-0.16247 0.1988 0.025"
      rpy="0 0 0" />
    <parent
      link="base_link" />
    <child
      link="link_BL" />
    <axis
      xyz="0 1 0" />
    <limit effort="10000" velocity="1000"/>
    <dynamics damping="1.0" friction="1.0"/>
  </joint>
  <link
    name="link_FL">
    <inertial>
      <origin
        xyz="0.00833663087142966 4.20500081946829E-05 0.0205298147363069"
        rpy="0 0 0" />
      <mass
        value="0.00119777212102609" />
      <inertia
        ixx="1.4519133714084E-07"
        ixy="2.45662593739392E-10"
        ixz="2.1644500368182E-08"
        iyy="9.64887007871609E-08"
        iyz="1.09174969107862E-10"
        izz="1.59814908753792E-07" />
    </inertial>
    <visual>
      <origin
        xyz="0 0 0"
        rpy="0 0 0" />
      <geometry>
        <mesh
          filename="install/slam/share/slam/meshes/link_FL1.STL" />
      </geometry>
      <material
        name="">
        <color
          rgba="0.792156862745098 0.819607843137255 0.933333333333333 1" />
      </material>
    </visual>
    <collision>
      <origin
        xyz="0 0 0"
        rpy="0 0 0" />
      <geometry>
        <mesh
          filename="install/slam/share/slam/meshes/link_FL1.STL" />
      </geometry>
    </collision>
  </link>
  <joint
    name="handle_L"
    type="fixed">
    <origin
      xyz="0.16253 0.1325 -0.026"
      rpy="0 0 0" />
    <parent
      link="base_link" />
    <child
      link="link_FL" />
    <axis
      xyz="0 0 1" />
  </joint>
  <link
    name="link_CL">
    <inertial>
      <origin
        xyz="-8.32667268468867E-17 -2.22044604925031E-16 0"
        rpy="0 0 0" />
      <mass
        value="0.0250867326043065" />
      <inertia
        ixx="3.28799571943433E-06"
        ixy="-6.37142975367367E-09"
        ixz="1.59676836869368E-22"
        iyy="4.55113237212099E-06"
        iyz="-1.04294217732024E-23"
        izz="3.28796358191049E-06" />
    </inertial>
    <visual>
      <origin
        xyz="0 0 0"
        rpy="0 0 0" />
      <geometry>
        <mesh
          filename="install/slam/share/slam/meshes/link_CL1.STL" />
      </geometry>
      <material
        name="">
        <color
          rgba="0.792156862745098 0.819607843137255 0.933333333333333 1" />
      </material>
    </visual>
    <collision>
      <origin
        xyz="0 0 0"
        rpy="0 0 0" />
      <geometry>
        <mesh
          filename="install/slam/share/slam/meshes/link_CL1.STL" />
      </geometry>
    </collision>
  </link>
  <joint
    name="caster_L"
    type="continuous">
    <origin
      xyz="0.0175 8.8269E-05 0.00375"
      rpy="0 0 0" />
    <parent
      link="link_FL" />
    <child
      link="link_CL" />
    <axis
      xyz="-0.0050439 0.99999 0" />
    <limit effort="10000" velocity="1000"/>
  </joint>
  <link
    name="link_FR">
    <inertial>
      <origin
        xyz="0.00833582277066608 0.000123455359173755 0.0205298147363069"
        rpy="0 0 0" />
      <mass
        value="0.00119777212102609" />
      <inertia
        ixx="1.45181895501399E-07"
        ixy="7.21175219840363E-10"
        ixz="2.16424022859297E-08"
        iyy="9.64981424266025E-08"
        iyz="3.20528713373724E-10"
        izz="1.59814908753793E-07" />
    </inertial>
    <visual>
      <origin
        xyz="0 0 0"
        rpy="0 0 0" />
      <geometry>
        <mesh
          filename="install/slam/share/slam/meshes/link_FR1.STL" />
      </geometry>
      <material
        name="">
        <color
          rgba="0.792156862745098 0.819607843137255 0.933333333333333 1" />
      </material>
    </visual>
    <collision>
      <origin
        xyz="0 0 0"
        rpy="0 0 0" />
      <geometry>
        <mesh
          filename="install/slam/share/slam/meshes/link_FR1.STL" />
      </geometry>
    </collision>
  </link>
  <joint
    name="handle_R"
    type="fixed">
    <origin
      xyz="0.16253 -0.1325 -0.026"
      rpy="0 0 0" />
    <parent
      link="base_link" />
    <child
      link="link_FR" />
    <axis
      xyz="0 0 1" />
  </joint>
  <link
    name="link_CR">
    <inertial>
      <origin
        xyz="-5.55111512312578E-16 -6.93889390390723E-16 -1.11022302462516E-16"
        rpy="0 0 0" />
      <mass
        value="0.0250867326043065" />
      <inertia
        ixx="3.28824059490171E-06"
        ixy="-1.87041795145209E-08"
        ixz="-4.02776208345378E-22"
        iyy="4.55088749665361E-06"
        iyz="-4.26046936299754E-22"
        izz="3.28796358191049E-06" />
    </inertial>
    <visual>
      <origin
        xyz="0 0 0"
        rpy="0 0 0" />
      <geometry>
        <mesh
          filename="install/slam/share/slam/meshes/link_CR1.STL" />
      </geometry>
      <material
        name="">
        <color
          rgba="0.792156862745098 0.819607843137255 0.933333333333333 1" />
      </material>
    </visual>
    <collision>
      <origin
        xyz="0 0 0"
        rpy="0 0 0" />
      <geometry>
        <mesh
          filename="install/slam/share/slam/meshes/link_CR1.STL" />
      </geometry>
    </collision>
  </link>
  <joint
    name="caster_R"
    type="continuous">
    <origin
      xyz="0.017498 0.00025915 0.00375"
      rpy="0 0 0" />
    <parent
      link="link_FR" />
    <child
      link="link_CR" />
    <axis
      xyz="0.014809 -0.99989 0" />
    <limit effort="10000" velocity="1000"/>
  </joint>
  <link name="hokuyo">
    <inertial>
      <mass value="1e-5"/>
      <origin rpy=" 0 0 0" xyz="0 0 0"/>
      <inertia ixx="1e-6" ixy="0" ixz="0" iyy="1e-6" iyz="0" izz="1e-6"/>
    </inertial>
    <visual name="hokuyo_visual">
      <origin rpy="0 0 0" xyz="0 0 0"/>
      <geometry>
        <box size="0.05 0.05 0.05"/>
      </geometry>
    </visual>
    <collision name="hokuyo_colision">
      <origin rpy="0 0 0" xyz="0 0 0"/>
      <geometry>
        <box size="0.1 0.1 0.1"/>
      </geometry>
    </collision>
  </link>
  <joint name="hokuyo_joint" type="fixed">
    <origin rpy="0 0 0" xyz="0 0 0.15"/>
    <child link="hokuyo"/>
    <parent link="base_link"/>
    <axis rpy="0 0 0" xyz="0 1 0"/>
  </joint>
  <gazebo reference="base_link">
    <material>Gazebo/Purple</material>
  </gazebo>
  <gazebo reference="link_BR">
    <material>Gazebo/Black</material>
  </gazebo>
  <gazebo reference="link_BL">
    <material>Gazebo/Black</material>
  </gazebo>
  <gazebo reference="link_CR">
    <material>Gazebo/Black</material>
  </gazebo>
  <gazebo reference="link_CL">
    <material>Gazebo/Black</material>
  </gazebo>
  <gazebo reference="hokuyo">
    <material>Gazebo/Black</material>
  </gazebo>
</robot>
